[32m2025-05-18 23:36:40 -0700[0m - dagster - [34mDEBUG[0m - __ASSET_JOB - b348f65d-19c8-4f91-a80b-f57f90487a74 - 90000 - LOGS_CAPTURED - Started capturing logs in process (pid: 90000).
[32m2025-05-18 23:36:40 -0700[0m - dagster - [34mDEBUG[0m - __ASSET_JOB - b348f65d-19c8-4f91-a80b-f57f90487a74 - 90000 - locate_privacy_policy - STEP_START - Started execution of step "locate_privacy_policy".
[32m2025-05-18 23:36:40 -0700[0m - dagster - [34mINFO[0m - __ASSET_JOB - b348f65d-19c8-4f91-a80b-f57f90487a74 - locate_privacy_policy - Navigating to honda.com
[32m2025-05-18 23:36:40.479[0m | [34m[1mDEBUG   [0m | [36mflashlight.workflow.resources.browser_manager[0m:[36mmanaged_context[0m:[36m43[0m - [34m[1mUsing User-Agent: %s[0m
[32m2025-05-18 23:36:40.828[0m | [1mINFO    [0m | [36mflashlight.workflow.resources.browser_manager[0m:[36mmanaged_context[0m:[36m52[0m - [1mClosing BrowserContext...[0m
[32m2025-05-18 23:36:40 -0700[0m - dagster - [34mERROR[0m - [31m__ASSET_JOB - b348f65d-19c8-4f91-a80b-f57f90487a74 - 90000 - locate_privacy_policy - STEP_FAILURE - Execution of step "locate_privacy_policy" failed.

dagster._core.errors.DagsterExecutionStepExecutionError: Error occurred while executing op "locate_privacy_policy"::

playwright._impl._errors.Error: Page.goto: Protocol error (Page.navigate): Cannot navigate to invalid URL
Call log:
  - navigating to "honda.com", waiting until "domcontentloaded"


Stack Trace:
  File "/Users/amrit/Desktop/CPPA/.venv/lib/python3.11/site-packages/dagster/_core/execution/plan/utils.py", line 56, in op_execution_error_boundary
    yield
  File "/Users/amrit/Desktop/CPPA/.venv/lib/python3.11/site-packages/dagster/_utils/__init__.py", line 392, in iterate_with_context
    next_output = next(iterator)
                  ^^^^^^^^^^^^^^
  File "/Users/amrit/Desktop/CPPA/flashlight/workflow/assets/find_privacy_policy.py", line 118, in locate_privacy_policy
    page.goto(
  File "/Users/amrit/Desktop/CPPA/.venv/lib/python3.11/site-packages/playwright/sync_api/_generated.py", line 9024, in goto
    self._sync(
  File "/Users/amrit/Desktop/CPPA/.venv/lib/python3.11/site-packages/playwright/_impl/_sync_base.py", line 115, in _sync
    return task.result()
           ^^^^^^^^^^^^^
  File "/Users/amrit/Desktop/CPPA/.venv/lib/python3.11/site-packages/playwright/_impl/_page.py", line 552, in goto
    return await self._main_frame.goto(**locals_to_params(locals()))
           ^^^^^^^^^^^^^^^^^^^^^^^^^^^^^^^^^^^^^^^^^^^^^^^^^^^^^^^^^
  File "/Users/amrit/Desktop/CPPA/.venv/lib/python3.11/site-packages/playwright/_impl/_frame.py", line 145, in goto
    await self._channel.send("goto", locals_to_params(locals()))
  File "/Users/amrit/Desktop/CPPA/.venv/lib/python3.11/site-packages/playwright/_impl/_connection.py", line 61, in send
    return await self._connection.wrap_api_call(
           ^^^^^^^^^^^^^^^^^^^^^^^^^^^^^^^^^^^^^
  File "/Users/amrit/Desktop/CPPA/.venv/lib/python3.11/site-packages/playwright/_impl/_connection.py", line 528, in wrap_api_call
    raise rewrite_error(error, f"{parsed_st['apiName']}: {error}") from None
[0m
